Workbook

Sheet pivot Table
A3: Row Labels | B3: Sum of Sales | E3: Row Labels | F3: Sum of Profit | H3: Row Labels | I3: Count of Sub-Category | K3: Row Labels | L3: Sum of Profit | N3: Row Labels | O3: Sum of Profit | Q3: Row Labels | R3: Sum of Cost | T3: Row Labels | U3: Sum of Sales | W3: Row Labels | X3: Sum of Profit | Z3: Row Labels | AA3: Sum of Profit | AC3: Row Labels | AD3: Sum of Sales | AF3: Row Labels | AG3: Sum of Profit | AI3: Row Labels | AJ3: Sum of Profit | AL3: Row Labels | AM3: Sum of Sales | AO3: Row Labels | AP3: Sum of Sales | AR3: Row Labels | AS3: Sum of Sales
A4: West | B4: 85938.698 | E4: Zipper Ring Binder Pockets | F4: 1.092 | H4: Accessories | I4: 89 | K4: Accessories | L4: 3774.697 | N4: Accessories | O4: 3774.697 | Q4: Accessories | R4: 11788.611 | T4: Yucaipa | U4: 50.8 | W4: Yucaipa | X4: 13.208 | Z4: West | AA4: 10658.656 | AC4: Alabama | AD4: 3398.77 | AF4: Alabama | AG4: 1164.6785 | AI4: First Class | AJ4: 6226.4003 | AL4: First Class | AM4: 47475.703 | AO4: Qtr1 | AP4: 65952.676 | AR4: 2016 | AS4: 87254.65
A5: East | B5: 79204.13 | E5: Zebra Zazzle Fluorescent Highlighters | F5: 6.8096 | H5: Appliances | I5: 65 | K5: Appliances | L5: 400.9911 | N5: Appliances | O5: 400.9911 | Q5: Appliances | R5: 12341.073 | T5: Yonkers | U5: 836.592 | W5: Yonkers | X5: -264.9208 | Z5: East | AA5: 6876.3469 | AC5: Arizona | AD5: 6333.347 | AF5: Arizona | AG5: -633.8371 | AI5: Same Day | AJ5: -3419.6167 | AL5: Same Day | AM5: 21953.12 | AO5: Qtr2 | AP5: 83469.853 | AR5: 2017 | AS5: 83419.188
A6: South | B6: 73200.182 | E6: XtraLife ClearVue Slant-D Ring Binders by Cardinal | F6: 15.68 | H6: Art | I6: 125 | K6: Art | L6: 1190.8152 | N6: Art | O6: 1190.8152 | Q6: Art | R6: 4375.9448 | T6: Woodstock | U6: 857.25 | W6: Woodstock | X6: -24.8859 | Z6: South | AA6: 3908.6048 | AC6: Arkansas | AD6: 1068.12 | AF6: Arkansas | AG6: 247.7324 | AI6: Second Class | AJ6: 4775.9715 | AL6: Second Class | AM6: 69113.215 | AO6: Qtr3 | AP6: 78154.546 | AR6: 2014 | AS6: 68842.39
A7: Central | B7: 69457.319 | E7: XtraLife ClearVue Slant-D Ring Binder, White, 3" | F7: 27.0112 | H7: Binders | I7: 180 | K7: Binders | L7: 6233.8576 | N7: Binders | O7: 6233.8576 | Q7: Binders | R7: 17012.576 | T7: Wilson | U7: 163.136 | W7: Wilson | X7: 20.392 | Z7: Central | AA7: 3519.0926 | AC7: California | AD7: 50679.191 | AF7: California | AG7: 8427.1182 | AI7: Standard Class | AJ7: 17379.945 | AL7: Standard Class | AM7: 169258.29 | AO7: Qtr4 | AP7: 80223.254 | AR7: 2015 | AS7: 68284.102
A8: Grand Total | B8: 307800.33 | E8: Xerox 227 | F8: 3.1104 | H8: Bookcases | I8: 34 | K8: Bookcases | L8: -2280.2007 | N8: Bookcases | O8: -2280.2007 | Q8: Bookcases | R8: 17981.41 | T8: Wilmington | U8: 622.82 | W8: Wilmington | X8: 100.1763 | Z8: Grand Total | AA8: 24962.7 | AC8: Colorado | AD8: 6648.098 | AF8: Colorado | AG8: -1612.4875 | AI8: Grand Total | AJ8: 24962.701 | AL8: Grand Total | AM8: 307800.33 | AO8: Grand Total | AP8: 307800.33 | AR8: Grand Total | AS8: 307800.33
E9: Xerox 226 | F9: 43.5456 | H9: Chairs | I9: 91 | K9: Chairs | L9: 3308.6781 | N9: Chairs | O9: 3308.6781 | Q9: Chairs | R9: 41286.949 | T9: Wichita | U9: 279.9 | W9: Wichita | X9: 137.151 | AC9: Connecticut | AD9: 1068.63 | AF9: Connecticut | AG9: 311.9351
E10: Xerox 224 | F10: 15.552 | H10: Copiers | I10: 6 | K10: Copiers | L10: 3036.9184 | N10: Copiers | O10: 3036.9184 | Q10: Copiers | R10: 4992.8616 | T10: Whittier | U10: 444.768 | W10: Whittier | X10: 44.4768 | AC10: Delaware | AD10: 992.566 | AF10: Delaware | AG10: 151.3549
E11: Xerox 223 | F11: 15.552 | H11: Envelopes | I11: 35 | K11: Envelopes | L11: 1138.8574 | N11: Envelopes | O11: 1138.8574 | Q11: Envelopes | R11: 1701.1286 | T11: Westminster | U11: 31.968 | W11: Westminster | X11: 2.3976 | Z11: Row Labels | AA11: Sum of Sales | AC11: District of Columbia | AD11: 62.82 | AF11: District of Columbia | AG11: 28.107
E12: Xerox 221 | F12: 7.2576 | H12: Fasteners | I12: 36 | K12: Fasteners | L12: 165.3945 | N12: Fasteners | O12: 165.3945 | Q12: Fasteners | R12: 312.2295 | T12: Westland | U12: 321.91 | W12: Westland | X12: 44.7619 | Z12: West | AA12: 85938.698 | AC12: Florida | AD12: 19065.395 | AF12: Florida | AG12: 50.7828
E13: Xerox 220 | F13: 9.3312 | H13: Furnishings | I13: 116 | K13: Furnishings | L13: 2032.8772 | N13: Furnishings | O13: 2032.8772 | Q13: Furnishings | R13: 10223.697 | T13: Westfield | U13: 228.53 | W13: Westfield | X13: 49.6204 | Z13: East | AA13: 79204.13 | AC13: Georgia | AD13: 6260.58 | AF13: Georgia | AG13: 1794.9069
E14: Xerox 219 | F14: 3.1104 | H14: Labels | I14: 57 | K14: Labels | L14: 766.8353 | N14: Labels | O14: 766.8353 | Q14: Labels | R14: 874.9287 | T14: West Palm Beach | U14: 13.12 | W14: West Palm Beach | X14: 2.132 | Z14: South | AA14: 73200.182 | AC14: Idaho | AD14: 368.248 | AF14: Idaho | AG14: 96.8631
E15: Xerox 218 | F15: 8.0352 | H15: Machines | I15: 15 | K15: Machines | L15: -952.9299 | N15: Machines | O15: -952.9299 | Q15: Machines | R15: 32288.229 | T15: West Jordan | U15: 55.5 | W15: West Jordan | X15: 9.99 | Z15: Central | AA15: 69457.319 | AC15: Illinois | AD15: 17293.1 | AF15: Illinois | AG15: -1864.3315
E16: Xerox 217 | F16: 5.4432 | H16: Paper | I16: 187 | K16: Paper | L16: 4307.4476 | N16: Paper | O16: 4307.4476 | Q16: Paper | R16: 5761.3944 | T16: West Allis | U16: 241.96 | W16: West Allis | X16: 24.196 | Z16: Grand Total | AA16: 307800.33 | AC16: Indiana | AD16: 2697.15 | AF16: Indiana | AG16: 590.8753
E17: Xerox 216 | F17: 24.8832 | H17: Phones | I17: 112 | K17: Phones | L17: 5839.2502 | N17: Phones | O17: 5839.2502 | Q17: Phones | R17: 43143.846 | T17: Waynesboro | U17: 673.65 | W17: Waynesboro | X17: 162.6678 | AC17: Iowa | AD17: 360.84 | AF17: Iowa | AG17: 106.6344
E18: Xerox 214 | F18: 3.1104 | H18: Storage | I18: 118 | K18: Storage | L18: 3316.2445 | N18: Storage | O18: 3316.2445 | Q18: Storage | R18: 33497.56 | T18: Watertown | U18: 931.83 | W18: Watertown | X18: 312.0687 | AC18: Kansas | AD18: 537.88 | AF18: Kansas | AG18: 211.9652
E19: Xerox 213 | F19: 6.2208 | H19: Supplies | I19: 16 | K19: Supplies | L19: -188.0361 | N19: Supplies | O19: -188.0361 | Q19: Supplies | R19: 2886.3941 | T19: Waterbury | U19: 65.17 | W19: Waterbury | X19: 18.8993 | AC19: Kentucky | AD19: 6164.13 | AF19: Kentucky | AG19: 1513.4779
E20: Xerox 212 | F20: 3.6288 | H20: Tables | I20: 52 | K20: Tables | L20: -7128.9969 | N20: Tables | O20: -7128.9969 | Q20: Tables | R20: 42368.797 | T20: Washington | U20: 62.82 | W20: Washington | X20: 28.107 | AC20: Louisiana | AD20: 779.68 | AF20: Louisiana | AG20: 189.101
E21: Xerox 211 | F21: 10.8864 | H21: Grand Total | I21: 1334 | K21: Grand Total | L21: 24962.7 | N21: Grand Total | O21: 24962.7 | Q21: Grand Total | R21: 282837.63 | T21: Warwick | U21: 49.96 | W21: Warwick | X21: 9.4924 | AC21: Maryland | AD21: 3194.56 | AF21: Maryland | AG21: 1516.7661
E22: Xerox 210 | F22: 3.6288 | T22: Warner Robins | U22: 392.94 | W22: Warner Robins | X22: 43.2234 | AC22: Massachusetts | AD22: 3864.134 | AF22: Massachusetts | AG22: 453.5503
E23: Xerox 21 | F23: 9.072 | T23: Virginia Beach | U23: 2726.89 | W23: Virginia Beach | X23: 1279.4463 | AC23: Michigan | AD23: 14277.682 | AF23: Michigan | AG23: 3510.3726
E24: Xerox 209 | F24: 9.3312 | T24: Vineland | U24: 244.006 | W24: Vineland | X24: -31.3722 | AC24: Minnesota | AD24: 3796.52 | AF24: Minnesota | AG24: 1190.069
E25: Xerox 208 | F25: 5.4432 | T25: Vancouver | U25: 68.46 | W25: Vancouver | X25: 21.1764 | AC25: Mississippi | AD25: 2667.01 | AF25: Mississippi | AG25: 738.1665
E26: Xerox 205 | F26: 24.8832 | T26: Vallejo | U26: 1078.8 | W26: Vallejo | X26: 287.592 | AC26: Missouri | AD26: 2647.51 | AF26: Missouri | AG26: 1032.6622
E27: Xerox 203 | F27: 5.4432 | T27: Vacaville | U27: 423.28 | W27: Vacaville | X27: 110.0528 | AC27: Montana | AD27: 3516.974 | AF27: Montana | AG27: 1546.4112
E28: Xerox 202 | F28: 9.3312 | T28: Urbandale | U28: 75.96 | W28: Urbandale | X28: 22.788 | AC28: Nebraska | AD28: 157.31 | AF28: Nebraska | AG28: 66.2248
E29: Xerox 2000 | F29: 7.2576 | T29: Tyler | U29: 2.688 | W29: Tyler | X29: -7.392 | AC29: Nevada | AD29: 2968.766 | AF29: Nevada | AG29: 569.1868
E30: Xerox 200 | F30: 6.2208 | T30: Tulsa | U30: 69.93 | W30: Tulsa | X30: 0.6993 | AC30: New Hampshire | AD30: 391.75 | AF30: New Hampshire | AG30: 89.9824
E31: Xerox 2 | F31: 19.9584 | T31: Tucson | U31: 700.128 | W31: Tucson | X31: 16.8544 | AC31: New Jersey | AD31: 13473.146 | AF31: New Jersey | AG31: 3405.083
E32: Xerox 1999 | F32: 6.2208 | T32: Troy | U32: 272.736 | W32: Troy | X32: 55.8516 | AC32: New Mexico | AD32: 824.73 | AF32: New Mexico | AG32: 222.8349
E33: Xerox 1997 | F33: 16.5888 | T33: Trenton | U33: 608.04 | W33: Trenton | X33: 301.698 | AC33: New York | AD33: 32297.718 | AF33: New York | AG33: 4971.7279
... E48: Xerox 1957 | F48: 9.396 | T48: Smyrna | U48: 121.756 | W48: Smyrna | X48: 6.2069 | AC48: Grand Total | AD48: 307800.33 | AF48: Grand Total | AG48: 24962.701
E49: Xerox 1955 | F49: 29.692 | T49: Sioux Falls | U49: 23.2 | W49: Sioux Falls | X49: 10.8149
E50: Xerox 1954 | F50: 15.312 | T50: Sierra Vista | U50: 45.928 | W50: Sierra Vista | X50: 13.8137
E51: Xerox 1953 | F51: 5.35 | T51: Seattle | U51: 9474.704 | W51: Seattle | X51: 1424.5462
E52: Xerox 195 | F52: 48.096 | T52: Scottsdale | U52: 190.26 | W52: Scottsdale | X52: -5.95
E53: Xerox 1949 | F53: 2.8884 | T53: Santa Barbara | U53: 1.81 | W53: Santa Barbara | X53: 0.6516
E54: Xerox 1947 | F54: 5.98 | T54: Santa Ana | U54: 18.28 | W54: Santa Ana | X54: 6.2152
E55: Xerox 1945 | F55: 83.2097 | T55: Sandy Springs | U55: 17.24 | W55: Sandy Springs | X55: 4.4824
E56: Xerox 1943 | F56: 45.9754 | T56: San Jose | U56: 387.7 | W56: San Jose | X56: 138.379
...

Sheet kpi
A1: Total Sales | B1: =SUM('Data set'!P:P) -> 307800.33
A2: Average Sales | B2: =B1/B3 -> 230.56204
A3: Total Order | B3: =COUNTA('Data set'!D:D) -> 1335
A4: Total Profit | B4: =SUM('Data set'!O:O) -> 24962.701
A5: Total Cost | B5: =SUM(Ecommerce_Sales_analysis[Cost]) -> 282837.63
A6: Total Quantity | B6: =SUM('Data set'!M:M) -> 5108
A7: Home Offfice Sales | B7: =SUMIF('Data set'!E:E,"Home Office",'Data set'!P:P) -> 55597.594
A8: consumer Sales | B8: =SUMIF('Data set'!E:E,"Consumer",'Data set'!P:P) -> 144286.99
A9: Corporate Sales | B9: =SUMIF('Data set'!E:E,"Corporate",'Data set'!P:P) -> 107915.74

Sheet Data set
A1: Order Date | B1: Ship Date | C1: Ship Mode | D1: Customer Name | E1: Segment | F1: Country | G1: City | H1: State | I1: Region | J1: Category | K1: Sub-Category | L1: Product Name | M1: Quantity | N1: Discount | O1: Profit | P1: Sales | Q1: Cost
A2: 42682 | B2: 42685 | C2: Second Class | D2: Claire Gute | E2: Consumer | F2: United States | G2: Henderson | H2: Kentucky | I2: South | J2: Furniture | K2: Bookcases | L2: Bush Somerset Collection Bookcase | M2: 2 | N2: 0 | O2: 41.9136 | P2: 261.96 | Q2: 220.0464
A3: 42533 | B3: 42537 | C3: Second Class | D3: Darrin Van Huff | E3: Corporate | F3: United States | G3: Los Angeles | H3: California | I3: West | J3: Office Supplies | K3: Labels | L3: Self-Adhesive Address Labels for Typewriters by Universal | M3: 2 | N3: 0 | O3: 6.8714 | P3: 14.62 | Q3: 7.7486
A4: 42288 | B4: 42295 | C4: Standard Class | D4: Sean O'Donnell | E4: Consumer | F4: United States | G4: Fort Lauderdale | H4: Florida | I4: South | J4: Furniture | K4: Tables | L4: Bretford CR4500 Series Slim Rectangular Table | M4: 5 | N4: 0.45 | O4: -383.031 | P4: 957.5775 | Q4: 1340.6085
A5: 41799 | B5: 41804 | C5: Standard Class | D5: Brosina Hoffman | E5: Consumer | F5: United States | G5: Los Angeles | H5: California | I5: West | J5: Furniture | K5: Furnishings | L5: Eldon Expressions Wood and Plastic Desk Accessories, Cherry Wood | M5: 7 | N5: 0 | O5: 14.1694 | P5: 48.86 | Q5: 34.6906
A6: 42840 | B6: 42845 | C6: Standard Class | D6: Andrew Allen | E6: Consumer | F6: United States | G6: Concord | H6: North Carolina | I6: South | J6: Office Supplies | K6: Paper | L6: Xerox 1967 | M6: 3 | N6: 0.2 | O6: 5.4432 | P6: 15.552 | Q6: 10.1088
A7: 42709 | B7: 42714 | C7: Standard Class | D7: Irene Maddox | E7: Consumer | F7: United States | G7: Seattle | H7: Washington | I7: West | J7: Office Supplies | K7: Binders | L7: Fellowes PB200 Plastic Comb Binding Machine | M7: 3 | N7: 0.2 | O7: 132.5922 | P7: 407.976 | Q7: 275.3838
A8: 42330 | B8: 42334 | C8: Standard Class | D8: Harold Pawlan | E8: Home Office | F8: United States | G8: Fort Worth | H8: Texas | I8: Central | J8: Office Supplies | K8: Appliances | L8: Holmes Replacement Filter for HEPA Air Cleaner, Very Large Room, HEPA Filter | M8: 5 | N8: 0.8 | O8: -123.858 | P8: 68.81 | Q8: 192.668
A9: 41954 | B9: 41961 | C9: Standard Class | D9: Pete Kriz | E9: Consumer | F9: United States | G9: Madison | H9: Wisconsin | I9: Central | J9: Office Supplies | K9: Storage | L9: Stur-D-Stor Shelving, Vertical 5-Shelf: 72"H x 36"W x 18 1/2"D | M9: 6 | N9: 0 | O9: 13.3176 | P9: 665.88 | Q9: 652.5624
A10: 41772 | B10: 41774 | C10: Second Class | D10: Alejandro Grove | E10: Consumer | F10: United States | G10: West Jordan | H10: Utah | I10: West | J10: Office Supplies | K10: Storage | L10: Fellowes Super Stor/Drawer | M10: 2 | N10: 0 | O10: 9.99 | P10: 55.5 | Q10: 45.51
A11: 41878 | B11: 41883 | C11: Second Class | D11: Zuschuss Donatelli | E11: Consumer | F11: United States | G11: San Francisco | H11: California | I11: West | J11: Office Supplies | K11: Art | L11: Newell 341 | M11: 2 | N11: 0 | O11: 2.4824 | P11: 8.56 | Q11: 6.0776
A12: 42713 | B12: 42717 | C12: Standard Class | D12: Ken Black | E12: Corporate | F12: United States | G12: Fremont | H12: Nebraska | I12: Central | J12: Office Supplies | K12: Art | L12: Newell 318 | M12: 7 | N12: 0 | O12: 5.0596 | P12: 19.46 | Q12: 14.4004
A13: 42932 | B13: 42934 | C13: Second Class | D13: Sandra Flanagan | E13: Consumer | F13: United States | G13: Philadelphia | H13: Pennsylvania | I13: East | J13: Furniture | K13: Chairs | L13: Global Deluxe Stacking Chair, Gray | M13: 2 | N13: 0.3 | O13: -1.0196 | P13: 71.372 | Q13: 72.3916
... A1335: 42792 | B1335: 42797 | C1335: Standard Class | D1335: Dave Brooks | E1335: Consumer | F1335: United States | G1335: Costa Mesa | H1335: California | I1335: West | J1335: Furniture | K1335: Furnishings | L1335: Tenex B1-RE Series Chair Mats for Low Pile Carpets | M1335: 2 | N1335: 0 | O1335: 15.6332 | P1335: 91.96 | Q1335: 76.3268

Sheet Index  of Deshboard
H7: Index of Deshboard
H9: S.No | I9: Deshboard Name
H10: 1 | I10: KPI Vs Analysis
H11: 2 | I11: Category Vs Analysis
H12: 3 | I12: City Vs Analysis
H13: 4 | I13: Region Vs Analysis
H14: 5 | I14: State VS Analysis
H15: 6 | I15: Sheap Mode Vs Analysis
H16: 7 | I16: Date Vs Analysis ( Quarter and Year)

Sheet KPI Deshboard
M3: Key perfomence indecater
M4: =kpi!A1 -> Total Sales | N4: =kpi!B1 -> 307800.33
M5: =kpi!A2 -> Average Sales | N5: =kpi!B2 -> 230.56204
M6: =kpi!A3 -> Total Order | N6: =kpi!B3 -> 1335
M7: =kpi!A4 -> Total Profit | N7: =kpi!B4 -> 24962.701
M8: =kpi!A5 -> Total Cost | N8: =kpi!B5 -> 282837.63
M9: =kpi!A6 -> Total Quantity | N9: =kpi!B6 -> 5108
M10: =kpi!A7 -> Home Offfice Sales | N10: =kpi!B7 -> 55597.594
M11: =kpi!A8 -> consumer Sales | N11: =kpi!B8 -> 144286.99
M12: =kpi!A9 -> Corporate Sales | N12: =kpi!B9 -> 107915.74

Sheet Category Vs Analysis

Sheet Category Vs profit

Sheet Category Vs Sales

Sheet Category vs Cost

Sheet City Vs Analysis

Sheet City Vs Profit

Sheet Region vs analysis

Sheet State Vs analysis

Sheet Stats Vs profit

Sheet Sheap Mode Vs Analysis

Sheet Date Vs Analysis
